<?xml version='1.0'?>

<robot name="robuter2" xmlns:xacro="http://www.ros.org/wiki/xacro">

  <xacro:property name="cameraSize" value="0.05"/>
  <xacro:property name="cameraMass" value="0.1"/>
  <xacro:property name="pi" value="3.1415926535897931" />
  <xacro:property name="pi2" value="1.5708" />

  <xacro:include filename="$(find mybot_description)/urdf/mybot.gazebo" />
  <xacro:include filename="$(find mybot_description)/urdf/materials.xacro" />
  <xacro:include filename="$(find mybot_description)/urdf/macros.xacro" />
  <xacro:include filename="$(find flir_ptu_description)/urdf/d46.urdf.xacro" />
   <xacro:include filename="$(find pointgrey_camera_description)/urdf/pointgrey_flea3.urdf.xacro" />

 

<!--NOTE: base_link was previously called chassis, check for this in case of error/-->
  <link name='chassis'>
    <pose>0 0 0.1 0 0 0</pose>

    <inertial>
      <mass value="15.0"/>
      <origin xyz="0.0 0 0.1" rpy=" 0 0 0"/>
      <inertia
          ixx="0.1" ixy="0" ixz="0"
          iyy="0.1" iyz="0"
          izz="0.1"
      />
    </inertial>

    <collision name='collision'>
      <geometry>
        <box size=".8 .535 .1"/>  <!--this alters the base/-->
      </geometry>
    </collision>

    <visual name='chassis_visual'>
      <origin xyz="0 0 0.15" rpy=" 0 0 0"/>
      <geometry>
        <box size=".8 .535 .35"/>
      </geometry>
      <material name="white">
        <color rgba="1 1 1 1"/>
      </material>
    </visual>


    

    <collision name='caster_front_collision'>
		
      <origin xyz="0.3 0 -0.05" rpy=" 0 0 0"/>
      <geometry>
        <sphere radius="0.05"/>
      </geometry>
      <surface>
        <friction>
          <ode>
            <mu>0</mu>
            <mu2>0</mu2>
            <slip1>1.0</slip1>
            <slip2>1.0</slip2>
          </ode>
        </friction>
      </surface>
    </collision>

    <visual name='caster_front_visual'>
      <origin xyz="0.3 0 -0.05" rpy=" 0 0 0"/>
      <geometry>
        <sphere radius="0.05"/>
      </geometry>
    </visual>

  </link>






  <link name="left_wheel">
    <!--origin xyz="0.1 0.13 0.1" rpy="0 1.5707 1.5707"/-->
    <collision name="collision">
      <origin xyz="0 0 0" rpy="0 ${pi2} ${pi2}"/>
      <geometry>
        <cylinder radius="0.1" length="0.06"/>
      </geometry>
    </collision>
    <visual name="left_wheel_visual">
      <origin xyz="0 0 0" rpy="0 ${pi2} ${pi2}"/>
      <geometry>
        <cylinder radius="0.1" length="0.06"/>
      </geometry>
       <material name="blue">
        <color rgba="0 0 1 1"/>
      </material>
    </visual>
    <inertial>
      <origin xyz="0 0 0" rpy="0 ${pi2} ${pi2}"/>
      <mass value="5"/>
      <inertia
        ixx=".1" ixy="0.0" ixz="0.0"
        iyy=".1" iyz="0.0"
        izz=".1"/>
    </inertial>
  </link>



  <link name="right_wheel">
    <!--origin xyz="0.1 -0.13 0.1" rpy="0 1.5707 1.5707"/-->
    <collision name="collision">
      <origin xyz="0 0 0" rpy="0 ${pi2} ${pi2}"/>
      <geometry>
        <cylinder radius="0.1" length="0.06"/>
      </geometry>
    </collision>
    <visual name="right_wheel_visual">
      <origin xyz="0 0 0" rpy="0 ${pi2} ${pi2}"/>
      <geometry>
        <cylinder radius="0.1" length="0.06"/>
      </geometry>
      <material name="blue">
        <color rgba="0 0 1 1"/>
      </material>
    </visual>
    <inertial>
      <origin xyz="0 0 0" rpy="0 ${pi2} ${pi2}"/>
      <mass value="5"/>
      <inertia
        ixx=".1" ixy="0.0" ixz="0.0"
        iyy=".1" iyz="0.0"
        izz=".1"/>
    </inertial>
  </link>


  <joint type="continuous" name="left_wheel_hinge">
    <origin xyz="-0.3 0.3 0" rpy="0 0 0"/>
    <!--origin xyz="0.1 0.13 0" rpy="0 1.5707 1.5707"/-->
    <child link="left_wheel"/>
    <parent link="chassis"/>
    <axis xyz="0 1 0" rpy="0 0 0"/>
    <limit effort="10000" velocity="1000"/>
    <joint_properties damping="1.0" friction="1.0"/>
  </joint>

  <joint type="continuous" name="right_wheel_hinge">
    <origin xyz="-0.3 -0.3 0" rpy="0 0 0"/>
    <!--origin xyz="0.1 -0.13 0" rpy="0 1.5707 1.5707"/-->
    <child link="right_wheel"/>
    <parent link="chassis"/>
    <axis xyz="0 1 0" rpy="0 0 0"/>
    <limit effort="10000" velocity="1000"/>
    <joint_properties damping="1.0" friction="1.0"/>
  </joint>






 

  <!-- PTU UNIT -->
  <!-- Create a fixed joint to connect the PTU to the rest of the robot -->
  <ptu_d46 name="ptu" />
  <joint name="base_to_ptu_base" type="fixed">
    <parent link="chassis"/>
    <child link="ptu_base_link"/>
    <origin xyz="0.4 0 0.35"/>
</joint>




<!-- FLEA CAMERA -->
<pointgrey_flea3 frame="flea3" name="flea3" camera_x="0.0754" camera_y="0.029" camera_z="0.035" camera_mass="0.085"
                   hfov="1.0471975512" fps="60" width="640" height="512"/>

  <joint name="world_camera_joint" type="fixed">
    <origin xyz="0 0 0.100" rpy="0 0 0" />
    <parent link="ptu_pan_link" />
    <child link="flea3" />
</joint>


</robot>

